<?xml version="1.0" ?>
<!-- =================================================================================== -->
<!-- |    This document was autogenerated by xacro from /home/murl/test3_ws/src/rldp5_description/urdf/rldp5.urdf.xacro | -->
<!-- |    EDITING THIS FILE BY HAND IS NOT RECOMMENDED                                 | -->
<!-- =================================================================================== -->
<robot name="rldp5">
    <!-- Links -->
    <link name="world" />
    <link name="base_link">
        <inertial>
            <origin rpy="0 0 0" xyz="0.04223218345086115 -0.01938787744257538 0.057495548139883904" />
            <mass value="2.4067491698035863" />
            <inertia ixx="0.008466" ixy="0.002277" ixz="-0.000705" iyy="0.018795" iyz="-0.000333" izz="0.024001" />
        </inertial>
        <visual>
            <origin rpy="0 0 0" xyz="0 0 0" />
            <geometry>
                <mesh filename="package://rldp5_description/mesh/base_link.stl" scale="0.001 0.001 0.001" />
            </geometry>
        </visual>
        <collision>
            <origin rpy="0 0 0" xyz="0 0 0" />
            <geometry>
                <mesh filename="package://rldp5_description/mesh/base_link.stl" scale="0.001 0.001 0.001" />
            </geometry>
        </collision>
    </link>
    <link name="link_1">
        <inertial>
            <origin rpy="0 0 0" xyz="0.02666189292548051 -4.87712308473133e-07 0.11114216106472456" />
            <mass value="2.489938203553284" />
            <inertia ixx="0.010589" ixy="3e-06" ixz="0.002056" iyy="0.021835" iyz="-0.0" izz="0.017706" />
        </inertial>
        <visual>
            <origin rpy="0 0 0" xyz="0.0 0.0 -0.1022" />
            <geometry>
                <mesh filename="package://rldp5_description/mesh/link_1.stl" scale="0.001 0.001 0.001" />
            </geometry>
        </visual>
        <collision>
            <origin rpy="0 0 0" xyz="0.0 0.0 -0.1022" />
            <geometry>
                <mesh filename="package://rldp5_description/mesh/link_1.stl" scale="0.001 0.001 0.001" />
            </geometry>
        </collision>
    </link>
    <link name="link_2">
        <inertial>
            <origin rpy="0 0 0" xyz="-0.0025797033685453323 0.08740384931769365 0.23089426213956546" />
            <mass value="1.7064644306239998" />
            <inertia ixx="0.027922" ixy="1.4e-05" ixz="0.000507" iyy="0.027117" iyz="-3.8e-05" izz="0.005495" />
        </inertial>
        <visual>
            <origin rpy="0 0 0" xyz="0.0 0.0875 -0.2472" />
            <geometry>
                <mesh filename="package://rldp5_description/mesh/link_2.stl" scale="0.001 0.001 0.001" />
            </geometry>
        </visual>
        <collision>
            <origin rpy="0 0 0" xyz="0.0 0.0875 -0.2472" />
            <geometry>
                <mesh filename="package://rldp5_description/mesh/link_2.stl" scale="0.001 0.001 0.001" />
            </geometry>
        </collision>
    </link>
    <link name="link_3">
        <inertial>
            <origin rpy="0 0 0" xyz="-0.17767994097579132 0.07055070946330594 -0.0021365928026594316" />
            <mass value="0.8476040154017905" />
            <inertia ixx="0.001758" ixy="-4e-06" ixz="-0.000161" iyy="0.008757" iyz="-3e-06" izz="0.008954" />
        </inertial>
        <visual>
            <origin rpy="0 0 0" xyz="0.0 0.0706 -0.5972" />
            <geometry>
                <mesh filename="package://rldp5_description/mesh/link_3.stl" scale="0.001 0.001 0.001" />
            </geometry>
        </visual>
        <collision>
            <origin rpy="0 0 0" xyz="0.0 0.0706 -0.5972" />
            <geometry>
                <mesh filename="package://rldp5_description/mesh/link_3.stl" scale="0.001 0.001 0.001" />
            </geometry>
        </collision>
    </link>
    <link name="link_4">
        <inertial>
            <origin rpy="0 0 0" xyz="-0.00026026868676498616 0.05460448637419659 -0.095038323418843" />
            <mass value="0.2564792674883184" />
            <inertia ixx="0.001174" ixy="-0.0" ixz="-1e-06" iyy="0.0011" iyz="0.0" izz="0.000275" />
        </inertial>
        <visual>
            <origin rpy="0 0 0" xyz="0.27 0.0546 -0.5972" />
            <geometry>
                <mesh filename="package://rldp5_description/mesh/link_4.stl" scale="0.001 0.001 0.001" />
            </geometry>
        </visual>
        <collision>
            <origin rpy="0 0 0" xyz="0.27 0.0546 -0.5972" />
            <geometry>
                <mesh filename="package://rldp5_description/mesh/link_4.stl" scale="0.001 0.001 0.001" />
            </geometry>
        </collision>
    </link>
    <link name="eef">
        <inertial>
            <origin rpy="0 0 0" xyz="-1.311241328183499e-06 2.1073781334110024e-05 -0.0010894994201211539" />
            <mass value="0.0722497566624133" />
            <inertia ixx="1.7e-05" ixy="-0.0" ixz="-0.0" iyy="1.7e-05" iyz="-0.0" izz="3.3e-05" />
        </inertial>
        <visual>
            <origin rpy="0 0 0" xyz="0.27 -0.0 -0.4132" />
            <geometry>
                <mesh filename="package://rldp5_description/mesh/eef.stl" scale="0.001 0.001 0.001" />
            </geometry>
        </visual>
        <collision>
            <origin rpy="0 0 0" xyz="0.27 -0.0 -0.4132" />
            <geometry>
                <mesh filename="package://rldp5_description/mesh/eef.stl" scale="0.001 0.001 0.001" />
            </geometry>
        </collision>
    </link>
    <link name="tl_link">
        <visual>
            <origin rpy="0 3.13 0" xyz="0 0 0" />
            <geometry>
                <mesh filename="package://rldp5_description/mesh/tool1.stl" />
            </geometry>
        </visual>
        <collision>
            <origin rpy="0 3.13 0" xyz="0 0 0" />
            <geometry>
                <mesh filename="package://rldp5_description/mesh/tool1.stl" />
            </geometry>
        </collision>
        <inertial>
            <mass value="0.1" />
            <origin xyz="0 0 0" rpy="0 0 0" />
            <inertia ixx="0.03" iyy="0.03" izz="0.03" ixy="0.0" ixz="0.0" iyz="0.0" />
        </inertial>
    </link>
    <link name="t2_link">
        <visual>
            <origin rpy="-1.57 0 0" xyz="-0.3 -0.2 0" />
            <geometry>
                <mesh filename="package://rldp5_description/mesh/tool2.stl" />
            </geometry>
        </visual>
        <collision>
            <origin rpy="0 0 0" xyz="0 0 0" />
            <geometry>
                <mesh filename="package://rldp5_description/mesh/tool2.stl" />
            </geometry>
        </collision>
        <inertial>
            <mass value="0.1" />
            <origin xyz="0 0 0" rpy="0 0 0" />
            <inertia ixx="0.03" iyy="0.03" izz="0.03" ixy="0.0" ixz="0.0" iyz="0.0" />
        </inertial>
    </link>
    <link name="tool_link" />
    <!-- Joints -->
    <joint name="virtual_joint" type="fixed">
        <parent link="world" />
        <child link="base_link" />
        <origin rpy="0 0 0" xyz="0 0 0" />
    </joint>
    <joint name="joint_1" type="revolute">
        <parent link="base_link" />
        <child link="link_1" />
        <origin xyz="0.0 0.0 0.1022" />
        <axis xyz="-0.0 0.0 -1.0" />
        <limit effort="10" lower="0.0" upper="3.141593" velocity="10" />
    </joint>
    <joint name="joint_2" type="revolute">
        <parent link="link_1" />
        <child link="link_2" />
        <origin xyz="0.0 -0.0875 0.145" />
        <axis xyz="0.0 1.0 0.0" />
        <limit effort="10" lower="-0.872665" upper="0.872665" velocity="10" />
    </joint>
    <joint name="joint_3" type="revolute">
        <parent link="link_2" />
        <child link="link_3" />
        <origin xyz="0.0 0.0169 0.35" />
        <axis xyz="0.0 1.0 0.0" />
        <limit effort="10" lower="-0.523599" upper="3.752458" velocity="10" />
    </joint>
    <joint name="joint_4" type="revolute">
        <parent link="link_3" />
        <child link="link_4" />
        <origin xyz="-0.27 0.016 0.0" />
        <axis xyz="0.0 1.0 0.0" />
        <limit effort="10" lower="-0.785398" upper="3.752458" velocity="10" />
    </joint>
    <joint name="joint_5" type="revolute">
        <parent link="link_4" />
        <child link="eef" />
        <origin xyz="0.0 0.0546 -0.184" />
        <axis xyz="0.0 0.0 -1.0" />
        <limit effort="10" lower="0.0" upper="6.283185" velocity="10" />
    </joint>
    <joint name="eef_to_tool" type="fixed">
        <parent link="eef" />
        <child link="tool_link" />
        <origin xyz="0 0 0" />
    </joint>
    <joint name="tool_joint" type="fixed">
        <parent link="eef" />
        <child link="tl_link" />
        <origin xyz="0 0 0" />
    </joint>
    <joint name="tool1_joint" type="fixed">
        <parent link="world" />
        <child link="t2_link" />
        <origin xyz="0 0 0" />
    </joint>
    <transmission name="transmission_1">
        <type>transmission_interface/SimpleTransmission</type>
        <joint name="joint_1">
            <hardwareInterface>hardware_interface/PositionJointInterface</hardwareInterface>
        </joint>
        <actuator name="motor_1">
            <hardwareInterface>hardware_interface/PositionJointInterface</hardwareInterface>
            <mechanicalReduction>1</mechanicalReduction>
        </actuator>
    </transmission>
    <transmission name="transmission_2">
        <type>transmission_interface/SimpleTransmission</type>
        <joint name="joint_2">
            <hardwareInterface>hardware_interface/PositionJointInterface</hardwareInterface>
        </joint>
        <actuator name="motor_2">
            <hardwareInterface>hardware_interface/PositionJointInterface</hardwareInterface>
            <mechanicalReduction>1</mechanicalReduction>
        </actuator>
    </transmission>
    <transmission name="transmission_3">
        <type>transmission_interface/SimpleTransmission</type>
        <joint name="joint_3">
            <hardwareInterface>hardware_interface/PositionJointInterface</hardwareInterface>
        </joint>
        <actuator name="motor_3">
            <hardwareInterface>hardware_interface/PositionJointInterface</hardwareInterface>
            <mechanicalReduction>1</mechanicalReduction>
        </actuator>
    </transmission>
    <transmission name="transmission_4">
        <type>transmission_interface/SimpleTransmission</type>
        <joint name="joint_4">
            <hardwareInterface>hardware_interface/PositionJointInterface</hardwareInterface>
        </joint>
        <actuator name="motor_4">
            <hardwareInterface>hardware_interface/PositionJointInterface</hardwareInterface>
            <mechanicalReduction>1</mechanicalReduction>
        </actuator>
    </transmission>
    <transmission name="transmission_5">
        <type>transmission_interface/SimpleTransmission</type>
        <joint name="joint_5">
            <hardwareInterface>hardware_interface/PositionJointInterface</hardwareInterface>
        </joint>
        <actuator name="motor_5">
            <hardwareInterface>hardware_interface/PositionJointInterface</hardwareInterface>
            <mechanicalReduction>1</mechanicalReduction>
        </actuator>
    </transmission>
    <material name="camera1_aluminum">
        <color rgba="0.5 0.5 0.5 1" />
    </material>
    <!-- camera body, with origin at bottom screw mount -->
    <joint name="camera1_joint" type="fixed">
        <origin rpy="0 1.57 1.57" xyz="-0.01 -0.06 -0.09" />
        <parent link="tl_link" />
        <child link="camera1_bottom_screw_frame" />
    </joint>
    <link name="camera1_bottom_screw_frame" />
    <joint name="camera1_link_joint" type="fixed">
        <origin rpy="0 0 0" xyz="0 0.0175 0.0125" />
        <parent link="camera1_bottom_screw_frame" />
        <child link="camera1_link" />
    </joint>
    <link name="camera1_link">
        <visual>
            <origin rpy="1.5707963267948966 0 1.5707963267948966" xyz="0.0149 -0.0175 0" />
            <geometry>
                <!-- <box size="${d435_cam_width} ${d435_cam_height} ${d435_cam_depth}"/> -->
                <mesh filename="package://realsense2_description/meshes/d435.dae" />
                <!--<mesh filename="package://realsense2_description/meshes/d435/d435.dae" />-->
            </geometry>
            <material name="camera1_aluminum" />
        </visual>
        <collision>
            <origin rpy="0 0 0" xyz="0 -0.0175 0" />
            <geometry>
                <box size="0.02505 0.09 0.025" />
            </geometry>
        </collision>
        <inertial>
            <!-- The following are not reliable values, and should not be used for modeling -->
            <mass value="0.564" />
            <origin xyz="0 0 0" rpy="0 0 0" />
            <inertia ixx="0.003881243" ixy="0.0" ixz="0.0" iyy="0.000498940" iyz="0.0" izz="0.003879257" />
        </inertial>
    </link>
    <!-- camera depth joints and links -->
    <joint name="camera1_depth_joint" type="fixed">
        <origin rpy="0 0 0" xyz="0 0 0" />
        <parent link="camera1_link" />
        <child link="camera1_depth_frame" />
    </joint>
    <link name="camera1_depth_frame" />
    <joint name="camera1_depth_optical_joint" type="fixed">
        <origin rpy="-1.5707963267948966 0 -1.5707963267948966" xyz="0 0 0" />
        <parent link="camera1_depth_frame" />
        <child link="camera1_depth_optical_frame" />
    </joint>
    <link name="camera1_depth_optical_frame" />
    <!-- camera left IR joints and links -->
    <joint name="camera1_left_ir_joint" type="fixed">
        <origin rpy="0 0 0" xyz="0 0.0 0" />
        <parent link="camera1_depth_frame" />
        <child link="camera1_left_ir_frame" />
    </joint>
    <link name="camera1_left_ir_frame" />
    <joint name="camera1_left_ir_optical_joint" type="fixed">
        <origin rpy="-1.5707963267948966 0 -1.5707963267948966" xyz="0 0 0" />
        <parent link="camera1_left_ir_frame" />
        <child link="camera1_left_ir_optical_frame" />
    </joint>
    <link name="camera1_left_ir_optical_frame" />
    <!-- camera right IR joints and links -->
    <joint name="camera1_right_ir_joint" type="fixed">
        <origin rpy="0 0 0" xyz="0 -0.05 0" />
        <parent link="camera1_depth_frame" />
        <child link="camera1_right_ir_frame" />
    </joint>
    <link name="camera1_right_ir_frame" />
    <joint name="camera1_right_ir_optical_joint" type="fixed">
        <origin rpy="-1.5707963267948966 0 -1.5707963267948966" xyz="0 0 0" />
        <parent link="camera1_right_ir_frame" />
        <child link="camera1_right_ir_optical_frame" />
    </joint>
    <link name="camera1_right_ir_optical_frame" />
    <!-- camera color joints and links -->
    <joint name="camera1_color_joint" type="fixed">
        <origin rpy="0 0 0" xyz="0 0.015 0" />
        <parent link="camera1_depth_frame" />
        <child link="camera1_color_frame" />
    </joint>
    <link name="camera1_color_frame" />
    <joint name="camera1_color_optical_joint" type="fixed">
        <origin rpy="-1.5707963267948966 0 -1.5707963267948966" xyz="0 0 0" />
        <parent link="camera1_color_frame" />
        <child link="camera1_color_optical_frame" />
    </joint>
    <link name="camera1_color_optical_frame" />
    <gazebo reference="camera1_link">
        <self_collide>0</self_collide>
        <enable_wind>0</enable_wind>
        <kinematic>0</kinematic>
        <gravity>1</gravity>
        <!--<mu>1</mu>-->
        <mu2>1</mu2>
        <fdir1>0 0 0</fdir1>
        <!--<slip1>0</slip1>
      <slip2>0</slip2>-->
        <kp>1e+13</kp>
        <kd>1</kd>
        <!--<max_vel>0.01</max_vel>
      <min_depth>0</min_depth>-->
        <sensor name="camera1color" type="camera">
            <camera name="camera1">
                <horizontal_fov>1.2112585008840648</horizontal_fov>
                <image>
                    <width>640</width>
                    <height>480</height>
                    <format>RGB_INT8</format>
                </image>
                <clip>
                    <near>0.1</near>
                    <far>100</far>
                </clip>
                <noise>
                    <type>gaussian</type>
                    <mean>0.0</mean>
                    <stddev>0.007</stddev>
                </noise>
            </camera>
            <always_on>1</always_on>
            <update_rate>30</update_rate>
            <visualize>1</visualize>
        </sensor>
        <sensor name="camera1ired1" type="camera">
            <camera name="camera1">
                <horizontal_fov>1.4870205226991688</horizontal_fov>
                <image>
                    <width>1280</width>
                    <height>720</height>
                    <format>L_INT8</format>
                </image>
                <clip>
                    <near>0.1</near>
                    <far>100</far>
                </clip>
                <noise>
                    <type>gaussian</type>
                    <mean>0.0</mean>
                    <stddev>0.05</stddev>
                </noise>
            </camera>
            <always_on>1</always_on>
            <update_rate>90</update_rate>
            <visualize>0</visualize>
        </sensor>
        <sensor name="camera1ired2" type="camera">
            <camera name="camera1">
                <horizontal_fov>1.4870205226991688</horizontal_fov>
                <image>
                    <width>1280</width>
                    <height>720</height>
                    <format>L_INT8</format>
                </image>
                <clip>
                    <near>0.1</near>
                    <far>100</far>
                </clip>
                <noise>
                    <type>gaussian</type>
                    <mean>0.0</mean>
                    <stddev>0.05</stddev>
                </noise>
            </camera>
            <always_on>1</always_on>
            <update_rate>90</update_rate>
            <visualize>0</visualize>
        </sensor>
        <sensor name="camera1depth" type="depth">
            <camera name="camera1">
                <horizontal_fov>1.4870205226991688</horizontal_fov>
                <image>
                    <width>1280</width>
                    <height>720</height>
                </image>
                <clip>
                    <near>0.1</near>
                    <far>100</far>
                </clip>
                <noise>
                    <type>gaussian</type>
                    <mean>0.0</mean>
                    <stddev>0.100</stddev>
                </noise>
            </camera>
            <always_on>1</always_on>
            <update_rate>90</update_rate>
            <visualize>0</visualize>
        </sensor>
        <plugin name="gazebo_ros_control">
            <robotNamespace>/</robotNamespace>
        </plugin>
    </gazebo>
    <gazebo>
        <plugin filename="librealsense_gazebo_plugin.so" name="camera1">
            <prefix>camera1</prefix>
            <depthUpdateRate>30.0</depthUpdateRate>
            <colorUpdateRate>30.0</colorUpdateRate>
            <infraredUpdateRate>30.0</infraredUpdateRate>
            <depthTopicName>depth/image_raw</depthTopicName>
            <depthCameraInfoTopicName>depth/camera_info</depthCameraInfoTopicName>
            <colorTopicName>color/image_raw</colorTopicName>
            <colorCameraInfoTopicName>color/camera_info</colorCameraInfoTopicName>
            <infrared1TopicName>infra1/image_raw</infrared1TopicName>
            <infrared1CameraInfoTopicName>infra1/camera_info</infrared1CameraInfoTopicName>
            <infrared2TopicName>infra2/image_raw</infrared2TopicName>
            <infrared2CameraInfoTopicName>infra2/camera_info</infrared2CameraInfoTopicName>
            <colorOpticalframeName>camera1_color_optical_frame</colorOpticalframeName>
            <depthOpticalframeName>camera1_depth_optical_frame</depthOpticalframeName>
            <infrared1OpticalframeName>camera1_left_ir_optical_frame</infrared1OpticalframeName>
            <infrared2OpticalframeName>camera1_right_ir_optical_frame</infrared2OpticalframeName>
            <rangeMinDepth>0.2</rangeMinDepth>
            <rangeMaxDepth>10.0</rangeMaxDepth>
            <pointCloud>True</pointCloud>
            <pointCloudTopicName>depth/color/points</pointCloudTopicName>
            <pointCloudCutoff>0.25</pointCloudCutoff>
            <pointCloudCutoffMax>9.0</pointCloudCutoffMax>
        </plugin>
    </gazebo>
    <!-- gazebo ros_control plugin -->
    <gazebo>
        <plugin filename="libgazebo_ros_control.so" name="gazebo_ros_control">
            <robotNamespace />
            <robotSimType>gazebo_ros_control/DefaultRobotHWSim</robotSimType>
            <legacyModeNS>true</legacyModeNS>
        </plugin>
    </gazebo>
</robot>

